<?xml version="1.0" ?>
<!-- Generated using onshape-to-robot -->
<!-- Onshape https://cad.onshape.com/documents/360c6fe247050cb2acb89595/w/0ec76884927e0d2c965064d4/e/8ad038c71909de84c50c460e -->
<robot name="robot">
  <!-- Link pelvis -->
  <link name="pelvis">
    <inertial>
      <origin xyz="0.000216195 -0.000649295 -0.000502195" rpy="0 0 0"/>
      <mass value="0.211284"/>
      <inertia ixx="0.000625526" ixy="-5.48372e-11" ixz="-2.17675e-10" iyy="0.000430078" iyz="-3.73841e-10" izz="0.000805235"/>
    </inertial>
    <!-- Part pelvis_lower -->
    <visual>
      <origin xyz="0.000216158 -0.000649359 -0.000502235" rpy="0 -0 0"/>
      <geometry>
        <mesh filename="package://assets/pelvis_lower.stl"/>
      </geometry>
      <material name="pelvis_lower_material">
        <color rgba="0.615686 0.811765 0.929412 1"/>
      </material>
    </visual>
    <collision>
      <origin xyz="0.000216158 -0.000649359 -0.000502235" rpy="0 -0 0"/>
      <geometry>
        <mesh filename="package://assets/pelvis_lower.stl"/>
      </geometry>
    </collision>
    <!-- Part pelvis_upper -->
    <visual>
      <origin xyz="0.000216158 -0.000649359 -0.000502235" rpy="0 -0 0"/>
      <geometry>
        <mesh filename="package://assets/pelvis_upper.stl"/>
      </geometry>
      <material name="pelvis_upper_material">
        <color rgba="0.615686 0.811765 0.929412 1"/>
      </material>
    </visual>
    <collision>
      <origin xyz="0.000216158 -0.000649359 -0.000502235" rpy="0 -0 0"/>
      <geometry>
        <mesh filename="package://assets/pelvis_upper.stl"/>
      </geometry>
    </collision>
  </link>
  <!-- Link l_shoulder_1 -->
  <link name="l_shoulder_1">
    <inertial>
      <origin xyz="0.0150409 0.000418622 -0.0361911" rpy="0 0 0"/>
      <mass value="0.1328"/>
      <inertia ixx="0.000134901" ixy="2.24108e-06" ixz="1.70356e-05" iyy="0.00011261" iyz="-1.62268e-06" izz="8.20386e-05"/>
    </inertial>
    <!-- Part shoulder -->
    <visual>
      <origin xyz="8.67362e-19 -3.25261e-19 -0.002" rpy="1.5708 -2.20919e-16 -1.5708"/>
      <geometry>
        <mesh filename="package://assets/shoulder.stl"/>
      </geometry>
      <material name="shoulder_material">
        <color rgba="0.615686 0.811765 0.929412 1"/>
      </material>
    </visual>
    <collision>
      <origin xyz="8.67362e-19 -3.25261e-19 -0.002" rpy="1.5708 -2.20919e-16 -1.5708"/>
      <geometry>
        <mesh filename="package://assets/shoulder.stl"/>
      </geometry>
    </collision>
  </link>
  <!-- Link l_shoulder_2 -->
  <link name="l_shoulder_2">
    <inertial>
      <origin xyz="-0.000418622 0.0183089 -0.0150409" rpy="0 0 0"/>
      <mass value="0.1328"/>
      <inertia ixx="0.00011261" ixy="1.62268e-06" ixz="2.24108e-06" iyy="8.20386e-05" iyz="-1.70356e-05" izz="0.000134901"/>
    </inertial>
    <!-- Part shoulder_2 -->
    <visual>
      <origin xyz="1.38778e-17 0.0525 0" rpy="-2.05377e-31 -3.54499e-31 5.59932e-18"/>
      <geometry>
        <mesh filename="package://assets/shoulder.stl"/>
      </geometry>
      <material name="shoulder_2_material">
        <color rgba="0.615686 0.811765 0.929412 1"/>
      </material>
    </visual>
    <collision>
      <origin xyz="1.38778e-17 0.0525 0" rpy="-2.05377e-31 -3.54499e-31 5.59932e-18"/>
      <geometry>
        <mesh filename="package://assets/shoulder.stl"/>
      </geometry>
    </collision>
  </link>
  <!-- Link l_thigh -->
  <link name="l_thigh">
    <inertial>
      <origin xyz="0.00177203 1.75905e-06 -0.0920004" rpy="0 0 0"/>
      <mass value="0.308571"/>
      <inertia ixx="0.00173378" ixy="-1.32373e-08" ixz="6.20201e-06" iyy="0.0017582" iyz="-2.38022e-08" izz="0.000264562"/>
    </inertial>
    <!-- Part thigh -->
    <visual>
      <origin xyz="1.38778e-17 6.93889e-18 -0.01" rpy="1.42548e-17 -2.86435e-17 3.2327e-17"/>
      <geometry>
        <mesh filename="package://assets/thigh.stl"/>
      </geometry>
      <material name="thigh_material">
        <color rgba="0.615686 0.811765 0.929412 1"/>
      </material>
    </visual>
    <collision>
      <origin xyz="1.38778e-17 6.93889e-18 -0.01" rpy="1.42548e-17 -2.86435e-17 3.2327e-17"/>
      <geometry>
        <mesh filename="package://assets/thigh.stl"/>
      </geometry>
    </collision>
    <!-- Part thigh_cover -->
    <visual>
      <origin xyz="-1.249e-16 1.45717e-16 -0.1225" rpy="1.5708 -3.41902e-16 -1.5708"/>
      <geometry>
        <mesh filename="package://assets/thigh_cover.stl"/>
      </geometry>
      <material name="thigh_cover_material">
        <color rgba="0.615686 0.811765 0.929412 1"/>
      </material>
    </visual>
    <collision>
      <origin xyz="-1.249e-16 1.45717e-16 -0.1225" rpy="1.5708 -3.41902e-16 -1.5708"/>
      <geometry>
        <mesh filename="package://assets/thigh_cover.stl"/>
      </geometry>
    </collision>
  </link>
  <!-- Link l_shin -->
  <link name="l_shin">
    <inertial>
      <origin xyz="8.63299e-17 0.111142 -0.009472" rpy="0 0 0"/>
      <mass value="0.14309"/>
      <inertia ixx="0.000865132" ixy="-2.38786e-19" ixz="9.92461e-12" iyy="1.70838e-05" iyz="2.32039e-07" izz="0.000870179"/>
    </inertial>
    <!-- Part shin_cover -->
    <visual>
      <origin xyz="-3.33067e-16 4.33681e-17 -0.0165" rpy="3.14159 -2.54525e-16 -6.96169e-15"/>
      <geometry>
        <mesh filename="package://assets/shin_cover.stl"/>
      </geometry>
      <material name="shin_cover_material">
        <color rgba="0.615686 0.811765 0.929412 1"/>
      </material>
    </visual>
    <collision>
      <origin xyz="-3.33067e-16 4.33681e-17 -0.0165" rpy="3.14159 -2.54525e-16 -6.96169e-15"/>
      <geometry>
        <mesh filename="package://assets/shin_cover.stl"/>
      </geometry>
    </collision>
    <!-- Part shin -->
    <visual>
      <origin xyz="-5.55112e-17 6.93889e-18 0" rpy="-3.14159 -8.99849e-18 -5.19499e-17"/>
      <geometry>
        <mesh filename="package://assets/shin.stl"/>
      </geometry>
      <material name="shin_material">
        <color rgba="0.615686 0.811765 0.929412 1"/>
      </material>
    </visual>
    <collision>
      <origin xyz="-5.55112e-17 6.93889e-18 0" rpy="-3.14159 -8.99849e-18 -5.19499e-17"/>
      <geometry>
        <mesh filename="package://assets/shin.stl"/>
      </geometry>
    </collision>
    <!-- Part foot -->
    <visual>
      <origin xyz="5.55112e-17 0.218564 -0.0095" rpy="1.5708 -1.5708 0"/>
      <geometry>
        <mesh filename="package://assets/foot.stl"/>
      </geometry>
      <material name="foot_material">
        <color rgba="0.615686 0.811765 0.929412 1"/>
      </material>
    </visual>
    <collision>
      <origin xyz="5.55112e-17 0.218564 -0.0095" rpy="1.5708 -1.5708 0"/>
      <geometry>
        <mesh filename="package://assets/foot.stl"/>
      </geometry>
    </collision>
  </link>
  <!-- Frame l_foot (dummy link + fixed joint) -->
  <link name="l_foot">
    <origin xyz="0 0 0" rpy="0 -0 0"/>
    <inertial>
      <origin xyz="0 0 0" rpy="0 0 0"/>
      <mass value="1e-9"/>
      <inertia ixx="0" ixy="0" ixz="0" iyy="0" iyz="0" izz="0"/>
    </inertial>
  </link>
  <joint name="l_foot_frame" type="fixed">
    <origin xyz="5.55112e-17 0.218564 -0.0095" rpy="1.5708 -1.5708 0"/>
    <parent link="l_shin"/>
    <child link="l_foot"/>
    <axis xyz="0 0 0"/>
  </joint>
  <!-- Joint from l_thigh to l_shin -->
  <joint name="l_knee" type="revolute">
    <origin xyz="0.0095 -1.66533e-16 -0.21" rpy="-1.5708 -1.39773 -1.5708"/>
    <parent link="l_thigh"/>
    <child link="l_shin"/>
    <axis xyz="0 0 1"/>
    <limit effort="10" velocity="10" lower="-1.35989" upper="4.15535"/>
  </joint>
  <!-- Joint from l_shoulder_2 to l_thigh -->
  <joint name="l_hip_ie" type="revolute">
    <origin xyz="0 0.0675 4.33681e-18" rpy="1.5708 0.417624 -8.86902e-16"/>
    <parent link="l_shoulder_2"/>
    <child link="l_thigh"/>
    <axis xyz="0 0 1"/>
    <limit effort="10" velocity="10" lower="-3.141592653589793" upper="3.141592653589793"/>
  </joint>
  <!-- Joint from l_shoulder_1 to l_shoulder_2 -->
  <joint name="l_hip_aa" type="revolute">
    <origin xyz="-0.002 5.08491e-17 -0.0545" rpy="-1.5708 1.31712 -1.5708"/>
    <parent link="l_shoulder_1"/>
    <child link="l_shoulder_2"/>
    <axis xyz="0 0 1"/>
    <limit effort="10" velocity="10" lower="-3.141592653589793" upper="3.141592653589793"/>
  </joint>
  <!-- Joint from pelvis to l_shoulder_1 -->
  <joint name="l_hip_fe" type="revolute">
    <origin xyz="0.0637162 -0.000649359 -0.000502235" rpy="-1.5708 -0 1.5708"/>
    <parent link="pelvis"/>
    <child link="l_shoulder_1"/>
    <axis xyz="0 0 1"/>
    <limit effort="10" velocity="10" lower="-6.28319" upper="0"/>
  </joint>
  <!-- Link r_shoulder_1 -->
  <link name="r_shoulder_1">
    <inertial>
      <origin xyz="0.0127339 0.00801567 -0.0361911" rpy="0 0 0"/>
      <mass value="0.1328"/>
      <inertia ixx="0.000127163" ixy="1.08459e-05" ixz="1.54899e-05" iyy="0.000120348" iyz="7.27381e-06" izz="8.20386e-05"/>
    </inertial>
    <!-- Part shoulder_3 -->
    <visual>
      <origin xyz="2.92735e-16 -2.88723e-16 -0.002" rpy="1.5708 1.04092e-15 -1.03681"/>
      <geometry>
        <mesh filename="package://assets/shoulder.stl"/>
      </geometry>
      <material name="shoulder_3_material">
        <color rgba="0.615686 0.811765 0.929412 1"/>
      </material>
    </visual>
    <collision>
      <origin xyz="2.92735e-16 -2.88723e-16 -0.002" rpy="1.5708 1.04092e-15 -1.03681"/>
      <geometry>
        <mesh filename="package://assets/shoulder.stl"/>
      </geometry>
    </collision>
  </link>
  <!-- Link r_shoulder_2 -->
  <link name="r_shoulder_2">
    <inertial>
      <origin xyz="-0.000418622 0.0183089 -0.0150409" rpy="0 0 0"/>
      <mass value="0.1328"/>
      <inertia ixx="0.00011261" ixy="1.62268e-06" ixz="2.24108e-06" iyy="8.20386e-05" iyz="-1.70356e-05" izz="0.000134901"/>
    </inertial>
    <!-- Part shoulder_4 -->
    <visual>
      <origin xyz="-1.38778e-17 0.0525 0" rpy="3.08204e-17 2.88676e-19 5.86289e-19"/>
      <geometry>
        <mesh filename="package://assets/shoulder.stl"/>
      </geometry>
      <material name="shoulder_4_material">
        <color rgba="0.615686 0.811765 0.929412 1"/>
      </material>
    </visual>
    <collision>
      <origin xyz="-1.38778e-17 0.0525 0" rpy="3.08204e-17 2.88676e-19 5.86289e-19"/>
      <geometry>
        <mesh filename="package://assets/shoulder.stl"/>
      </geometry>
    </collision>
  </link>
  <!-- Link r_thigh -->
  <link name="r_thigh">
    <inertial>
      <origin xyz="0.00177203 1.75905e-06 -0.0920004" rpy="0 0 0"/>
      <mass value="0.308571"/>
      <inertia ixx="0.00173378" ixy="-1.32373e-08" ixz="6.20201e-06" iyy="0.0017582" iyz="-2.38022e-08" izz="0.000264562"/>
    </inertial>
    <!-- Part thigh_cover_2 -->
    <visual>
      <origin xyz="3.60822e-16 9.62772e-17 -0.1225" rpy="1.5708 -3.87832e-16 -1.5708"/>
      <geometry>
        <mesh filename="package://assets/thigh_cover.stl"/>
      </geometry>
      <material name="thigh_cover_2_material">
        <color rgba="0.615686 0.811765 0.929412 1"/>
      </material>
    </visual>
    <collision>
      <origin xyz="3.60822e-16 9.62772e-17 -0.1225" rpy="1.5708 -3.87832e-16 -1.5708"/>
      <geometry>
        <mesh filename="package://assets/thigh_cover.stl"/>
      </geometry>
    </collision>
    <!-- Part thigh_2 -->
    <visual>
      <origin xyz="-1.38778e-17 -6.93889e-18 -0.01" rpy="7.73029e-17 -2.66957e-19 -5.85952e-21"/>
      <geometry>
        <mesh filename="package://assets/thigh.stl"/>
      </geometry>
      <material name="thigh_2_material">
        <color rgba="0.615686 0.811765 0.929412 1"/>
      </material>
    </visual>
    <collision>
      <origin xyz="-1.38778e-17 -6.93889e-18 -0.01" rpy="7.73029e-17 -2.66957e-19 -5.85952e-21"/>
      <geometry>
        <mesh filename="package://assets/thigh.stl"/>
      </geometry>
    </collision>
  </link>
  <!-- Link r_shin -->
  <link name="r_shin">
    <inertial>
      <origin xyz="1.27243e-16 -0.111142 0.009472" rpy="0 0 0"/>
      <mass value="0.14309"/>
      <inertia ixx="0.000865132" ixy="-5.22731e-19" ixz="-9.92461e-12" iyy="1.70838e-05" iyz="2.32039e-07" izz="0.000870179"/>
    </inertial>
    <!-- Part shin_cover_2 -->
    <visual>
      <origin xyz="0 -3.46945e-17 0.0165" rpy="-1.92271e-15 -5.16599e-16 1.97423e-15"/>
      <geometry>
        <mesh filename="package://assets/shin_cover.stl"/>
      </geometry>
      <material name="shin_cover_2_material">
        <color rgba="0.615686 0.811765 0.929412 1"/>
      </material>
    </visual>
    <collision>
      <origin xyz="0 -3.46945e-17 0.0165" rpy="-1.92271e-15 -5.16599e-16 1.97423e-15"/>
      <geometry>
        <mesh filename="package://assets/shin_cover.stl"/>
      </geometry>
    </collision>
    <!-- Part foot_2 -->
    <visual>
      <origin xyz="-5.55112e-17 -0.218564 0.0095" rpy="-1.5708 -1.5708 0"/>
      <geometry>
        <mesh filename="package://assets/foot.stl"/>
      </geometry>
      <material name="foot_2_material">
        <color rgba="0.615686 0.811765 0.929412 1"/>
      </material>
    </visual>
    <collision>
      <origin xyz="-5.55112e-17 -0.218564 0.0095" rpy="-1.5708 -1.5708 0"/>
      <geometry>
        <mesh filename="package://assets/foot.stl"/>
      </geometry>
    </collision>
    <!-- Part shin_2 -->
    <visual>
      <origin xyz="5.55112e-17 -2.08167e-17 -2.77556e-17" rpy="-9.96722e-19 -6.21353e-19 -5.2524e-17"/>
      <geometry>
        <mesh filename="package://assets/shin.stl"/>
      </geometry>
      <material name="shin_2_material">
        <color rgba="0.615686 0.811765 0.929412 1"/>
      </material>
    </visual>
    <collision>
      <origin xyz="5.55112e-17 -2.08167e-17 -2.77556e-17" rpy="-9.96722e-19 -6.21353e-19 -5.2524e-17"/>
      <geometry>
        <mesh filename="package://assets/shin.stl"/>
      </geometry>
    </collision>
  </link>
  <!-- Frame r_foot (dummy link + fixed joint) -->
  <link name="r_foot">
    <origin xyz="0 0 0" rpy="0 -0 0"/>
    <inertial>
      <origin xyz="0 0 0" rpy="0 0 0"/>
      <mass value="1e-9"/>
      <inertia ixx="0" ixy="0" ixz="0" iyy="0" iyz="0" izz="0"/>
    </inertial>
  </link>
  <joint name="r_foot_frame" type="fixed">
    <origin xyz="-5.55112e-17 -0.218564 0.0095" rpy="-1.5708 -1.5708 0"/>
    <parent link="r_shin"/>
    <child link="r_foot"/>
    <axis xyz="0 0 0"/>
  </joint>
  <!-- Joint from r_thigh to r_shin -->
  <joint name="r_knee" type="revolute">
    <origin xyz="0.0095 -2.64545e-16 -0.21" rpy="1.5708 1.50583 -1.5708"/>
    <parent link="r_thigh"/>
    <child link="r_shin"/>
    <axis xyz="0 0 1"/>
    <limit effort="10" velocity="10" lower="-1.25179" upper="4.26345"/>
  </joint>
  <!-- Joint from r_shoulder_2 to r_thigh -->
  <joint name="r_hip_ie" type="revolute">
    <origin xyz="-2.77556e-17 0.0675 2.73219e-17" rpy="-1.5708 -0.0205571 -3.14159"/>
    <parent link="r_shoulder_2"/>
    <child link="r_thigh"/>
    <axis xyz="0 0 1"/>
    <limit effort="10" velocity="10" lower="-3.141592653589793" upper="3.141592653589793"/>
  </joint>
  <!-- Joint from r_shoulder_1 to r_shoulder_2 -->
  <joint name="r_hip_aa" type="revolute">
    <origin xyz="-0.00172157 -0.00101794 -0.0545" rpy="1.5708 -1.56004 2.10478"/>
    <parent link="r_shoulder_1"/>
    <child link="r_shoulder_2"/>
    <axis xyz="0 0 1"/>
    <limit effort="10" velocity="10" lower="-3.141592653589793" upper="3.141592653589793"/>
  </joint>
  <!-- Joint from pelvis to r_shoulder_1 -->
  <joint name="r_hip_fe" type="revolute">
    <origin xyz="-0.0632838 -0.000649359 -0.000502235" rpy="1.5708 -0 1.5708"/>
    <parent link="pelvis"/>
    <child link="r_shoulder_1"/>
    <axis xyz="0 0 1"/>
    <limit effort="10" velocity="10" lower="-0.533985" upper="5.7492"/>
  </joint>
</robot>
